Workbook
Name ADDRESS: #REF!
Name AddressLine1: 'Input Form'!$B$4
Name AddressLine2: 'Input Form'!$B$5
Name AddressLine3: 'Input Form'!$B$6
Name BasicPackage: 'Input Form'!$A$19
Name BasicPackagePrice: 'Input Form'!$B$19
Name CompanyName: 'Input Form'!$B$3
Name CUSTOMER: #REF!
Name CustomerName: 'Input Form'!$B$2
Name DE: #REF!
Name MenuPackage1: 'Input Form'!$A$20
Name MenuPackage1Price: 'Input Form'!$B$20
Name MenuPackage2: 'Input Form'!$A$21
Name MenuPackage2Price: 'Input Form'!$B$21
Name MenuPackage3: 'Input Form'!$A$22
Name MenuPackage3Price: 'Input Form'!$B$22
Name MenuPackage4: 'Input Form'!$A$23
Name MenuPackagePrice4: 'Input Form'!$B$23

Sheet Input Form
A1: CUSTOMER INFORMATION
A2: Customer Name | B2: Evan Dailey
A3: Company Name | B3: Express Car Wash
A4: Address Line 1
A5: Address Line 2 | B5: 231 MacCorkle Ave SW
A6: Address Line 3 | B6: South Charleston, WV 25303
A8: Weekly Hours of Operation | B8: Average Daily Wash Hours
A9: 84 | B9: =A9/7 -> 12
A11: LABOR
A12: Position | B12: Labor Hours | C12: Hourly Wages | D12: Burden Rate
A13: Manager | B13: 49 | C13: 25 | D13: 0.2
A14: Assistant Manager | B14: 42 | C14: 20 | D14: 0.2
A15: Attendants | B15: 160 | C15: 12 | D15: 0.2
A17: WASH PACKAGES
A18: Packages | B18: Price | C18: Chemical Costs | D18: % of Customers
A19: Basic Package | B19: 5 | C19: 0.45 | D19: 0.65
A20: Menu Package #1 | B20: 10 | C20: 0.886 | D20: 0.15
A21: Menu Package #2 | B21: 15 | C21: 1.054 | D21: 0.12
A22: Menu Package #3 | B22: 20 | C22: 1.873 | D22: 0.04
A23: Menu Package #4 | B23: 25 | C23: 2.121 | D23: 0.04
A25: WASH PACKAGE CHANGES - YEAR 2 THROUGH YEAR 5
A26: Packages | B26: Year 2 Price | C26: Year 3 Price | D26: Year 4 Price | E26: Year 5 Price
A27: Basic Package | B27: 5 | C27: 5 | D27: 5 | E27: 5
A28: Menu Package #1 | B28: 10 | C28: 10 | D28: 10 | E28: 10
A29: Menu Package #2 | B29: 15 | C29: 15 | D29: 15 | E29: 15
A30: Menu Package #3 | B30: 20 | C30: 20 | D30: 20 | E30: 20
A31: Menu Package #4 | B31: 25 | C31: 25 | D31: 25 | E31: 25
A33: SITE - SPECIFIC FACTORS
A34: Area Profile | B34: Shopping | C34: Business | D34: Residential | E34: Industrial | F34: Site Score
C35: 1 | F35: =IF(B35=1,0.15,IF(C35=1,0.1,IF(D35=1,0.05,IF(E35=1,-0.25,0)))) -> 0.1
A36: Nearest Competition | B36: One in 4 Miles | C36: Multiple in 4 Miles | D36: One in 2 Miles | E36: Multiple in 2 Miles | F36: Site Score
C37: 1 | F37: =IF(B37=1,0.15,IF(C37=1,0.125,IF(D37=1,0.075,IF(E37=1,-0.025,0)))) -> 0.125
A38: Weekly Hours of Operation | B38: More Than 70 Hours | C38: 65 - 70 Hours | D38: 60 - 64 Hours | E38: Less Than 60 Hours | F38: Site Score
B39: 1 | F39: =IF(B39=1,0.15,IF(C39=1,0.1,IF(D39=1,0.025,IF(E39=1,0,0)))) -> 0.15
A40: Type of Site | B40: Corner Lot With Light | C40: Corner Lot Without Light | D40: Inside Lot Near Light | E40: Inside Lot No Light | F40: Site Score
B41: 1 | F41: =IF(B41=1,0.15,IF(C41=1,0.125,IF(D41=1,0.075,IF(E41=1,0.05,0)))) -> 0.15
A42: Site Accessibility | B42: Easy In & Easy Out | C42: Easy In/Out With Divided Highway | D42: Easy In Or Easy Out One Way | E42: Difficult In and Out | F42: Site Score
B43: 1 | F43: =IF(B43=1,0.15,IF(C43=1,0.1,IF(D43=1,0.05,IF(E43=1,0,0)))) -> 0.15
A44: Entrance Stack Up Area | B44: More Than 20 Vehicles | C44: 20 - 15 Vehicles | D44: 14 - 10 Vehicles | E44: Less Than 10 Vehicles | F44: Site Score
C45: 1 | F45: =IF(B45=1,0.15,IF(C45=1,0.125,IF(D45=1,0.075,IF(E45=1,0.05,0)))) -> 0.125
...

Sheet Pro Forma
A27: Exterior Express Car Wash Pro Forma
E28: Prepared For:
E29: ='Input Form'!B2 -> Evan Dailey
E30: ='Input Form'!B3 -> Express Car Wash
E31: ='Input Form'!B4 -> 0
E32: ='Input Form'!B5 -> 231 MacCorkle Ave SW
E33: ='Input Form'!B6 -> South Charleston, WV 25303
B40: Sonny's Enterprises, LLC, it's affiliates, and subsidiaries make no guarantees, representations, or warranties as to the accuracy of specific forecasts, projections, or predictive statements contained herein. Many factors impact the operation and profitability of a car wash that cannot be predicted or built into financial models and projections. The information provided herein is not intended to replace or serve as a substitute for any legal, real estate, tax, or other professional advice, consultation, or service. You assume any and all risk relying on these projections. Original on file at SONNY'S. This proforma does not include additional volume or income generated from a Monthly Unlimited Program. This proforma cannot account for the population density:# of
B46: market competitors ratio or the shared traffic pattern.
B53: Exterior Express Car Wash Pro Forma
C56: Name | E56: =CustomerName -> Evan Dailey
C57: Company | E57: =CompanyName -> Express Car Wash
C58: Address | E58: =AddressLine1 -> 0
E59: =AddressLine2 -> 231 MacCorkle Ave SW
E60: =AddressLine3 -> South Charleston, WV 25303
B63: BREAK EVEN ANALYSIS
B64: Monthly Wash Volume | I64: Break Even | J64: Year One
I65: =IFERROR((('Input Form'!F94+'Input Form'!E100+'Pro Forma'!I83+'Pro Forma'!I84+'Pro Forma'!I89)/('Pro Forma'!J77*(1-('Pro Forma'!G80+'Pro Forma'!G81+'Pro Forma'!G82+'Pro Forma'!G85+'Pro Forma'!G86+'Pro Forma'!G87+'Pro Forma'!G88+'Pro Forma'!G90+'Pro Forma'!G91)))),0) -> 4042.8113 | J65: ='Input Form'!B75 -> 4906.997
B66: Revenue
B67: On-Line Service Description | F67: Price Per Unit | G67: Percentage of Customers | I67: Average Monthly
I68: Break Even | J68: Year One
B69: =BasicPackage -> Basic Package | F69: ='Input Form'!B19 -> 5 | G69: ='Input Form'!D19 -> 0.65 | I69: =IFERROR((I$65*G69*F69),0) -> 13139.137 | J69: =J$65*F69*G69 -> 15947.74
B70: =MenuPackage1 -> Menu Package #1 | F70: ='Input Form'!B20 -> 10 | G70: ='Input Form'!D20 -> 0.15 | I70: =IFERROR((I$65*G70*F70),0) -> 6064.2169 | J70: =J$65*F70*G70 -> 7360.4955
B71: =MenuPackage2 -> Menu Package #2 | F71: ='Input Form'!B21 -> 15 | G71: ='Input Form'!D21 -> 0.12 | I71: =IFERROR((I$65*G71*F71),0) -> 7277.0603 | J71: =J$65*F71*G71 -> 8832.5946
B72: =MenuPackage3 -> Menu Package #3 | F72: ='Input Form'!B22 -> 20 | G72: ='Input Form'!D22 -> 0.04 | I72: =I$65*G72*F72 -> 3234.249 | J72: =J$65*F72*G72 -> 3925.5976
B73: =MenuPackage4 -> Menu Package #4 | F73: ='Input Form'!B23 -> 25 | G73: ='Input Form'!D23 -> 0.04 | I73: =I$65*G73*F73 -> 4042.8113 | J73: =J$65*F73*G73 -> 4906.997
B74: Total On-Line Revenue | I74: =SUM(I69:I73) -> 33757.474 | J74: =SUM(J69:J73) -> 40973.425
B75: Bank and Credit Card Fees | F75: 0.03 | G75: 0.75 | I75: =-(I74*$F75*$G75) -> -759.54317 | J75: =-(J74*$F75*$G75) -> -921.90206
B76: Total Revenue | I76: =SUM(I74:I75) -> 32997.931 | J76: =SUM(J74:J75) -> 40051.523
B77: Total Revenue Per Car | I77: =IFERROR((I76/I65),0) -> 8.162125 | J77: =J76/(J65+0.000000001) -> 8.162125
B78: Operational Expenses
B79: Expense Description | G79: % of Sales | I79: Break Even | J79: Year 1
B80: Advertisements and Promotions | G80: 0.03 | I80: =$G80*I76 -> 989.93793 | J80: =$G80*J76 -> 1201.5457
B81: Chemical Supplies | G81: =IFERROR((J81/J74),0) -> 0.085226347 | I81: =G81*I76 -> 2812.2931 | J81: =('Input Form'!B75*'Input Form'!D19*'Input Form'!C19)+('Input Form'!B75*'Input Form'!C20*'Input Form'!D20)+('Input Form'!B75*'Input Form'!C21*'Input Form'!D21)+('Input Form'!B75*'Input Form'!C22*'Input Form'!D22)+('Input Form'!B75*'Input Form'!C23*'Input Form'!D23) -> 3492.0154
B82: Customer Claims | G82: 0.01 | I82: =$G82*I76 -> 329.97931 | J82: =$G82*J76 -> 400.51523
B83: Insurance | G83: =IFERROR((I83/I74),0) -> 0.029623069 | I83: 1000 | J83: =I83 -> 1000
B84: Labor | G84: =IFERROR((I84/I74),0) -> 0.63425954 | I84: =J84 -> 21411 | J84: =IFERROR(((('Input Form'!B13-40)*'Input Form'!C13*1.5*52/12*(1+'Input Form'!D13)+(40*'Input Form'!C13*52/12*(1+'Input Form'!D13))+(('Input Form'!B14-40)*'Input Form'!C14*1.5*52/12*(1+'Input Form'!D14))+('Input Form'!C14*40*52/12*(1+'Input Form'!D14))+('Input Form'!B15*'Input Form'!C15*52/12*(1+'Input Form'!D14)))),0) -> 21411
B85: Legal and Professional Fees | G85: 0.01 | I85: =$G85*I76 -> 329.97931 | J85: =$G85*J76 -> 400.51523
B86: Licenses and Taxes | G86: 0.01 | I86: =$G86*I76 -> 329.97931 | J86: =$G86*J76 -> 400.51523
B87: Miscellaneous | G87: 0.015 | I87: =$G87*I76 -> 494.96897 | J87: =$G87*J76 -> 600.77285
...
